[2024-01-31T08:16:45.823+0000] {scheduler_job_runner.py:781} ERROR - Executor reports task instance <TaskInstance: sample_python_dag.harder_task scheduled__2024-01-30T00:00:00+00:00 [queued]> finished (failed) although the task says it's queued. (Info: None) Was the task killed externally?
