[2024-01-31T09:24:56.946+0000] {taskinstance.py:1956} INFO - Dependencies all met for dep_context=non-requeueable deps ti=<TaskInstance: classification_basic_1.evaluation manual__2024-01-31T09:14:19.877041+00:00 [queued]>
[2024-01-31T09:24:56.957+0000] {taskinstance.py:1956} INFO - Dependencies all met for dep_context=requeueable deps ti=<TaskInstance: classification_basic_1.evaluation manual__2024-01-31T09:14:19.877041+00:00 [queued]>
[2024-01-31T09:24:56.958+0000] {taskinstance.py:2170} INFO - Starting attempt 2 of 2
[2024-01-31T09:24:56.989+0000] {taskinstance.py:2191} INFO - Executing <Task(_PythonDecoratedOperator): evaluation> on 2024-01-31 09:14:19.877041+00:00
[2024-01-31T09:24:57.000+0000] {standard_task_runner.py:60} INFO - Started process 1080 to run task
[2024-01-31T09:24:57.005+0000] {standard_task_runner.py:87} INFO - Running: ['***', 'tasks', 'run', 'classification_basic_1', 'evaluation', 'manual__2024-01-31T09:14:19.877041+00:00', '--job-id', '44', '--raw', '--subdir', 'DAGS_FOLDER/imt/classification_simple_demo/classification_simple.py', '--cfg-path', '/tmp/tmpg6yqgv4m']
[2024-01-31T09:24:57.007+0000] {standard_task_runner.py:88} INFO - Job 44: Subtask evaluation
[2024-01-31T09:24:57.082+0000] {task_command.py:423} INFO - Running <TaskInstance: classification_basic_1.evaluation manual__2024-01-31T09:14:19.877041+00:00 [running]> on host 4e7d18d461d0
[2024-01-31T09:24:57.180+0000] {taskinstance.py:2480} INFO - Exporting env vars: AIRFLOW_CTX_DAG_EMAIL='ledatascientist@ds.com' AIRFLOW_CTX_DAG_OWNER='***' AIRFLOW_CTX_DAG_ID='classification_basic_1' AIRFLOW_CTX_TASK_ID='evaluation' AIRFLOW_CTX_EXECUTION_DATE='2024-01-31T09:14:19.877041+00:00' AIRFLOW_CTX_TRY_NUMBER='2' AIRFLOW_CTX_DAG_RUN_ID='manual__2024-01-31T09:14:19.877041+00:00'
[2024-01-31T09:25:18.970+0000] {taskinstance.py:2698} ERROR - Task failed with exception
Traceback (most recent call last):
  File "/home/airflow/.local/lib/python3.8/site-packages/airflow/models/taskinstance.py", line 433, in _execute_task
    result = execute_callable(context=context, **execute_callable_kwargs)
  File "/home/airflow/.local/lib/python3.8/site-packages/airflow/decorators/base.py", line 241, in execute
    return_value = super().execute(context)
  File "/home/airflow/.local/lib/python3.8/site-packages/airflow/operators/python.py", line 199, in execute
    return_value = self.execute_callable()
  File "/home/airflow/.local/lib/python3.8/site-packages/airflow/operators/python.py", line 216, in execute_callable
    return self.python_callable(*self.op_args, **self.op_kwargs)
  File "/opt/airflow/dags/imt/classification_simple_demo/validation_task.py", line 44, in start_evaluation
    model = load(model_path / "model.joblib")
  File "/home/airflow/.local/lib/python3.8/site-packages/joblib/numpy_pickle.py", line 650, in load
    with open(filename, 'rb') as f:
FileNotFoundError: [Errno 2] No such file or directory: '/opt/airflow/models/model.joblib'
[2024-01-31T09:25:18.995+0000] {taskinstance.py:1138} INFO - Marking task as FAILED. dag_id=classification_basic_1, task_id=evaluation, execution_date=20240131T091419, start_date=20240131T092456, end_date=20240131T092518
[2024-01-31T09:25:19.019+0000] {standard_task_runner.py:107} ERROR - Failed to execute job 44 for task evaluation ([Errno 2] No such file or directory: '/opt/airflow/models/model.joblib'; 1080)
[2024-01-31T09:25:19.080+0000] {local_task_job_runner.py:234} INFO - Task exited with return code 1
[2024-01-31T09:25:19.103+0000] {taskinstance.py:3280} INFO - 0 downstream tasks scheduled from follow-on schedule check
