[2024-01-31T09:14:01.949+0000] {taskinstance.py:1956} INFO - Dependencies all met for dep_context=non-requeueable deps ti=<TaskInstance: classification_basic_1.preparation manual__2024-01-31T09:13:58.839796+00:00 [queued]>
[2024-01-31T09:14:01.959+0000] {taskinstance.py:1956} INFO - Dependencies all met for dep_context=requeueable deps ti=<TaskInstance: classification_basic_1.preparation manual__2024-01-31T09:13:58.839796+00:00 [queued]>
[2024-01-31T09:14:01.960+0000] {taskinstance.py:2170} INFO - Starting attempt 1 of 2
[2024-01-31T09:14:01.992+0000] {taskinstance.py:2191} INFO - Executing <Task(_PythonDecoratedOperator): preparation> on 2024-01-31 09:13:58.839796+00:00
[2024-01-31T09:14:02.003+0000] {standard_task_runner.py:60} INFO - Started process 631 to run task
[2024-01-31T09:14:02.008+0000] {standard_task_runner.py:87} INFO - Running: ['***', 'tasks', 'run', 'classification_basic_1', 'preparation', 'manual__2024-01-31T09:13:58.839796+00:00', '--job-id', '15', '--raw', '--subdir', 'DAGS_FOLDER/imt/classification_simple_demo/classification_simple.py', '--cfg-path', '/tmp/tmppi0k8xgg']
[2024-01-31T09:14:02.010+0000] {standard_task_runner.py:88} INFO - Job 15: Subtask preparation
[2024-01-31T09:14:02.066+0000] {task_command.py:423} INFO - Running <TaskInstance: classification_basic_1.preparation manual__2024-01-31T09:13:58.839796+00:00 [running]> on host 4e7d18d461d0
[2024-01-31T09:14:02.164+0000] {taskinstance.py:2480} INFO - Exporting env vars: AIRFLOW_CTX_DAG_EMAIL='ledatascientist@ds.com' AIRFLOW_CTX_DAG_OWNER='***' AIRFLOW_CTX_DAG_ID='classification_basic_1' AIRFLOW_CTX_TASK_ID='preparation' AIRFLOW_CTX_EXECUTION_DATE='2024-01-31T09:13:58.839796+00:00' AIRFLOW_CTX_TRY_NUMBER='1' AIRFLOW_CTX_DAG_RUN_ID='manual__2024-01-31T09:13:58.839796+00:00'
[2024-01-31T09:14:02.167+0000] {logging_mixin.py:188} INFO - /opt/***/data
[2024-01-31T09:14:03.282+0000] {taskinstance.py:2698} ERROR - Task failed with exception
Traceback (most recent call last):
  File "/home/airflow/.local/lib/python3.8/site-packages/airflow/models/taskinstance.py", line 433, in _execute_task
    result = execute_callable(context=context, **execute_callable_kwargs)
  File "/home/airflow/.local/lib/python3.8/site-packages/airflow/decorators/base.py", line 241, in execute
    return_value = super().execute(context)
  File "/home/airflow/.local/lib/python3.8/site-packages/airflow/operators/python.py", line 199, in execute
    return_value = self.execute_callable()
  File "/home/airflow/.local/lib/python3.8/site-packages/airflow/operators/python.py", line 216, in execute_callable
    return self.python_callable(*self.op_args, **self.op_kwargs)
  File "/opt/airflow/dags/imt/classification_simple_demo/prepare_task.py", line 36, in start_preparation
    save_as_csv(train_files, train_labels, prepared / "train.csv")
  File "/opt/airflow/dags/imt/classification_simple_demo/prepare_task.py", line 24, in save_as_csv
    data_frame.to_csv(destination)
  File "/home/airflow/.local/lib/python3.8/site-packages/pandas/core/generic.py", line 3772, in to_csv
    return DataFrameRenderer(formatter).to_csv(
  File "/home/airflow/.local/lib/python3.8/site-packages/pandas/io/formats/format.py", line 1186, in to_csv
    csv_formatter.save()
  File "/home/airflow/.local/lib/python3.8/site-packages/pandas/io/formats/csvs.py", line 240, in save
    with get_handle(
  File "/home/airflow/.local/lib/python3.8/site-packages/pandas/io/common.py", line 737, in get_handle
    check_parent_directory(str(handle))
  File "/home/airflow/.local/lib/python3.8/site-packages/pandas/io/common.py", line 600, in check_parent_directory
    raise OSError(rf"Cannot save file into a non-existent directory: '{parent}'")
OSError: Cannot save file into a non-existent directory: '/opt/***/data/prepared'
[2024-01-31T09:14:03.307+0000] {taskinstance.py:1138} INFO - Marking task as UP_FOR_RETRY. dag_id=classification_basic_1, task_id=preparation, execution_date=20240131T091358, start_date=20240131T091401, end_date=20240131T091403
[2024-01-31T09:14:03.330+0000] {standard_task_runner.py:107} ERROR - Failed to execute job 15 for task preparation (Cannot save file into a non-existent directory: '/opt/***/data/prepared'; 631)
[2024-01-31T09:14:03.348+0000] {local_task_job_runner.py:234} INFO - Task exited with return code 1
[2024-01-31T09:14:03.373+0000] {taskinstance.py:3280} INFO - 0 downstream tasks scheduled from follow-on schedule check
